{
 "cells": [
  {
   "cell_type": "markdown",
   "metadata": {},
   "source": [
    "# Actual Data Classification"
   ]
  },
  {
   "cell_type": "markdown",
   "metadata": {},
   "source": [
    "## Packages and Stuff"
   ]
  },
  {
   "cell_type": "code",
   "execution_count": 18,
   "metadata": {},
   "outputs": [],
   "source": [
    "import numpy as np\n",
    "import pandas as pd\n",
    "import matplotlib.pyplot as plt\n",
    "from numpy import loadtxt\n",
    "from keras.models import Sequential\n",
    "from keras.layers import Conv2D, MaxPooling2D, Dense, Flatten\n",
    "from keras.utils import to_categorical\n",
    "from keras import optimizers, losses\n",
    "\n",
    "from sklearn import preprocessing\n",
    "\n",
    "import pickle"
   ]
  },
  {
   "cell_type": "markdown",
   "metadata": {},
   "source": [
    "## Dealing with Data Crap"
   ]
  },
  {
   "cell_type": "markdown",
   "metadata": {},
   "source": [
    "### Training Data"
   ]
  },
  {
   "cell_type": "code",
   "execution_count": 19,
   "metadata": {},
   "outputs": [
    {
     "name": "stderr",
     "output_type": "stream",
     "text": [
      "ERROR:root:Internal Python error in the inspect module.\n",
      "Below is the traceback from this internal error.\n",
      "\n"
     ]
    },
    {
     "name": "stdout",
     "output_type": "stream",
     "text": [
      "Traceback (most recent call last):\n",
      "  File \"/Users/collopa/anaconda3/lib/python3.7/site-packages/IPython/core/interactiveshell.py\", line 3331, in run_code\n",
      "    exec(code_obj, self.user_global_ns, self.user_ns)\n",
      "  File \"<ipython-input-19-a290de084a26>\", line 1, in <module>\n",
      "    with open(\"/Users/collopa/Desktop/nonlinear/project/Colin_Eli_Kai_Math178_Final/data/train_vectors/train_features.pkl\", \"rb\") \\\n",
      "FileNotFoundError: [Errno 2] No such file or directory: '/Users/collopa/Desktop/nonlinear/project/Colin_Eli_Kai_Math178_Final/data/train_vectors/train_features.pkl'\n",
      "\n",
      "During handling of the above exception, another exception occurred:\n",
      "\n",
      "Traceback (most recent call last):\n",
      "  File \"/Users/collopa/anaconda3/lib/python3.7/site-packages/IPython/core/interactiveshell.py\", line 2044, in showtraceback\n",
      "    stb = value._render_traceback_()\n",
      "AttributeError: 'FileNotFoundError' object has no attribute '_render_traceback_'\n",
      "\n",
      "During handling of the above exception, another exception occurred:\n",
      "\n",
      "Traceback (most recent call last):\n",
      "  File \"/Users/collopa/anaconda3/lib/python3.7/site-packages/IPython/core/ultratb.py\", line 1148, in get_records\n",
      "    return _fixed_getinnerframes(etb, number_of_lines_of_context, tb_offset)\n",
      "  File \"/Users/collopa/anaconda3/lib/python3.7/site-packages/IPython/core/ultratb.py\", line 316, in wrapped\n",
      "    return f(*args, **kwargs)\n",
      "  File \"/Users/collopa/anaconda3/lib/python3.7/site-packages/IPython/core/ultratb.py\", line 350, in _fixed_getinnerframes\n",
      "    records = fix_frame_records_filenames(inspect.getinnerframes(etb, context))\n",
      "  File \"/Users/collopa/anaconda3/lib/python3.7/inspect.py\", line 1502, in getinnerframes\n",
      "    frameinfo = (tb.tb_frame,) + getframeinfo(tb, context)\n",
      "  File \"/Users/collopa/anaconda3/lib/python3.7/inspect.py\", line 1460, in getframeinfo\n",
      "    filename = getsourcefile(frame) or getfile(frame)\n",
      "  File \"/Users/collopa/anaconda3/lib/python3.7/inspect.py\", line 696, in getsourcefile\n",
      "    if getattr(getmodule(object, filename), '__loader__', None) is not None:\n",
      "  File \"/Users/collopa/anaconda3/lib/python3.7/inspect.py\", line 725, in getmodule\n",
      "    file = getabsfile(object, _filename)\n",
      "  File \"/Users/collopa/anaconda3/lib/python3.7/inspect.py\", line 709, in getabsfile\n",
      "    return os.path.normcase(os.path.abspath(_filename))\n",
      "  File \"/Users/collopa/anaconda3/lib/python3.7/posixpath.py\", line 383, in abspath\n",
      "    cwd = os.getcwd()\n",
      "PermissionError: [Errno 1] Operation not permitted\n"
     ]
    },
    {
     "ename": "FileNotFoundError",
     "evalue": "[Errno 2] No such file or directory: '/Users/collopa/Desktop/nonlinear/project/Colin_Eli_Kai_Math178_Final/data/train_vectors/train_features.pkl'",
     "output_type": "error",
     "traceback": [
      "\u001b[0;31m---------------------------------------------------------------------------\u001b[0m"
     ]
    }
   ],
   "source": [
    "with open(\"/Users/collopa/Desktop/nonlinear/project/Colin_Eli_Kai_Math178_Final/data/train_vectors/train_features.pkl\", \"rb\") \\\n",
    "        as input_file:  train_features = pickle.load(input_file)\n",
    "    \n",
    "with open(\"/Users/collopa/Desktop/nonlinear/project/Colin_Eli_Kai_Math178_Final/data/train_vectors/train_labels.pkl\", \"rb\") \\\n",
    "    as input_file:  train_labels = pickle.load(input_file)"
   ]
  },
  {
   "cell_type": "markdown",
   "metadata": {},
   "source": [
    "### Testing Data"
   ]
  },
  {
   "cell_type": "code",
   "execution_count": 20,
   "metadata": {},
   "outputs": [
    {
     "name": "stderr",
     "output_type": "stream",
     "text": [
      "ERROR:root:Internal Python error in the inspect module.\n",
      "Below is the traceback from this internal error.\n",
      "\n"
     ]
    },
    {
     "name": "stdout",
     "output_type": "stream",
     "text": [
      "Traceback (most recent call last):\n",
      "  File \"/Users/collopa/anaconda3/lib/python3.7/site-packages/IPython/core/interactiveshell.py\", line 3331, in run_code\n",
      "    exec(code_obj, self.user_global_ns, self.user_ns)\n",
      "  File \"<ipython-input-20-9bf241fceec6>\", line 1, in <module>\n",
      "    with open(\"/Users/collopa/Desktop/nonlinear/project/Colin_Eli_Kai_Math178_Final/data/test_vectors/test_features.pkl\", \"rb\") \\\n",
      "FileNotFoundError: [Errno 2] No such file or directory: '/Users/collopa/Desktop/nonlinear/project/Colin_Eli_Kai_Math178_Final/data/test_vectors/test_features.pkl'\n",
      "\n",
      "During handling of the above exception, another exception occurred:\n",
      "\n",
      "Traceback (most recent call last):\n",
      "  File \"/Users/collopa/anaconda3/lib/python3.7/site-packages/IPython/core/interactiveshell.py\", line 2044, in showtraceback\n",
      "    stb = value._render_traceback_()\n",
      "AttributeError: 'FileNotFoundError' object has no attribute '_render_traceback_'\n",
      "\n",
      "During handling of the above exception, another exception occurred:\n",
      "\n",
      "Traceback (most recent call last):\n",
      "  File \"/Users/collopa/anaconda3/lib/python3.7/site-packages/IPython/core/ultratb.py\", line 1148, in get_records\n",
      "    return _fixed_getinnerframes(etb, number_of_lines_of_context, tb_offset)\n",
      "  File \"/Users/collopa/anaconda3/lib/python3.7/site-packages/IPython/core/ultratb.py\", line 316, in wrapped\n",
      "    return f(*args, **kwargs)\n",
      "  File \"/Users/collopa/anaconda3/lib/python3.7/site-packages/IPython/core/ultratb.py\", line 350, in _fixed_getinnerframes\n",
      "    records = fix_frame_records_filenames(inspect.getinnerframes(etb, context))\n",
      "  File \"/Users/collopa/anaconda3/lib/python3.7/inspect.py\", line 1502, in getinnerframes\n",
      "    frameinfo = (tb.tb_frame,) + getframeinfo(tb, context)\n",
      "  File \"/Users/collopa/anaconda3/lib/python3.7/inspect.py\", line 1460, in getframeinfo\n",
      "    filename = getsourcefile(frame) or getfile(frame)\n",
      "  File \"/Users/collopa/anaconda3/lib/python3.7/inspect.py\", line 696, in getsourcefile\n",
      "    if getattr(getmodule(object, filename), '__loader__', None) is not None:\n",
      "  File \"/Users/collopa/anaconda3/lib/python3.7/inspect.py\", line 725, in getmodule\n",
      "    file = getabsfile(object, _filename)\n",
      "  File \"/Users/collopa/anaconda3/lib/python3.7/inspect.py\", line 709, in getabsfile\n",
      "    return os.path.normcase(os.path.abspath(_filename))\n",
      "  File \"/Users/collopa/anaconda3/lib/python3.7/posixpath.py\", line 383, in abspath\n",
      "    cwd = os.getcwd()\n",
      "PermissionError: [Errno 1] Operation not permitted\n"
     ]
    },
    {
     "ename": "FileNotFoundError",
     "evalue": "[Errno 2] No such file or directory: '/Users/collopa/Desktop/nonlinear/project/Colin_Eli_Kai_Math178_Final/data/test_vectors/test_features.pkl'",
     "output_type": "error",
     "traceback": [
      "\u001b[0;31m---------------------------------------------------------------------------\u001b[0m"
     ]
    }
   ],
   "source": [
    "with open(\"/Users/collopa/Desktop/nonlinear/project/Colin_Eli_Kai_Math178_Final/data/test_vectors/test_features.pkl\", \"rb\") \\\n",
    "        as input_file:  test_features = pickle.load(input_file)\n",
    "    \n",
    "with open(\"/Users/collopa/Desktop/nonlinear/project/Colin_Eli_Kai_Math178_Final/data/test_vectors/test_labels.pkl\", \"rb\") \\\n",
    "    as input_file:  test_labels = pickle.load(input_file)"
   ]
  },
  {
   "cell_type": "markdown",
   "metadata": {},
   "source": [
    "## Reproducing a Neural Network"
   ]
  },
  {
   "cell_type": "markdown",
   "metadata": {},
   "source": [
    "Trying to reproduce results from \"Human Activity Recognition Based on Deep Learning Techniques\" by Manuel Gil-MartiÃÅn, et al. on their raw data."
   ]
  },
  {
   "cell_type": "code",
   "execution_count": 21,
   "metadata": {},
   "outputs": [
    {
     "data": {
      "text/plain": [
       "array([[1., 0., 0., 0., 0., 0.],\n",
       "       [1., 0., 0., 0., 0., 0.],\n",
       "       [1., 0., 0., 0., 0., 0.],\n",
       "       ...,\n",
       "       [0., 0., 0., 1., 0., 0.],\n",
       "       [0., 0., 0., 1., 0., 0.],\n",
       "       [0., 0., 0., 1., 0., 0.]], dtype=float32)"
      ]
     },
     "execution_count": 21,
     "metadata": {},
     "output_type": "execute_result"
    }
   ],
   "source": [
    "#training set\n",
    "#acceleroation dataset\n",
    "train_f = np.array(train_features)\n",
    "train_f = train_f.reshape(len(train_f), 128, 12)\n",
    "train_a_data = train_f[:int(0.8 * len(train_f)),:, 0:3]\n",
    "\n",
    "train_a_truth = test_labels\n",
    "train_label_encoder = preprocessing.LabelEncoder()\n",
    "train_truth = train_label_encoder.fit_transform(train_a_truth)\n",
    "to_categorical(train_truth)"
   ]
  },
  {
   "cell_type": "code",
   "execution_count": 22,
   "metadata": {},
   "outputs": [
    {
     "name": "stdout",
     "output_type": "stream",
     "text": [
      "4079 13460 0\n"
     ]
    },
    {
     "data": {
      "text/plain": [
       "array([[1., 0., 0., 0., 0., 0.],\n",
       "       [1., 0., 0., 0., 0., 0.],\n",
       "       [1., 0., 0., 0., 0., 0.],\n",
       "       ...,\n",
       "       [0., 0., 0., 1., 0., 0.],\n",
       "       [0., 0., 0., 1., 0., 0.],\n",
       "       [0., 0., 0., 1., 0., 0.]], dtype=float32)"
      ]
     },
     "execution_count": 22,
     "metadata": {},
     "output_type": "execute_result"
    }
   ],
   "source": [
    "train_vec = train_truth[:int(0.8 * len(train_truth))]\n",
    "\n",
    "#validation set\n",
    "val_a_data = train_a_data[int(0.8 * len(train_a_data)):]\n",
    "val_vec = train_truth[int(0.8 * len(train_a_data)):]\n",
    "\n",
    "print(len(train_vec), len(train_a_data), len(val_vec))\n",
    "\n",
    "#test set\n",
    "#acceleration dataset\n",
    "test_f = np.array(test_features)\n",
    "test_f = test_f.reshape(len(test_f), 128, 12)\n",
    "test_a_data = test_f[:,:, 0:3]\n",
    "test_a_truth = test_labels\n",
    "\n",
    "truth_label_encoder = preprocessing.LabelEncoder()\n",
    "test_vec = truth_label_encoder.fit_transform(test_a_truth)\n",
    "to_categorical(test_vec)"
   ]
  },
  {
   "cell_type": "markdown",
   "metadata": {},
   "source": [
    "### Build DNN Model"
   ]
  },
  {
   "cell_type": "code",
   "execution_count": 23,
   "metadata": {},
   "outputs": [
    {
     "name": "stdout",
     "output_type": "stream",
     "text": [
      "WARNING:tensorflow:From /Users/collopa/anaconda3/lib/python3.7/site-packages/keras/backend/tensorflow_backend.py:4070: The name tf.nn.max_pool is deprecated. Please use tf.nn.max_pool2d instead.\n",
      "\n"
     ]
    },
    {
     "name": "stderr",
     "output_type": "stream",
     "text": [
      "WARNING:tensorflow:From /Users/collopa/anaconda3/lib/python3.7/site-packages/keras/backend/tensorflow_backend.py:4070: The name tf.nn.max_pool is deprecated. Please use tf.nn.max_pool2d instead.\n",
      "\n"
     ]
    }
   ],
   "source": [
    "model = Sequential()\n",
    "\n",
    "model.add(Conv2D(16, (15,1),  \\\n",
    "                 input_shape = (128, 3,1), \n",
    "                 activation='relu')\n",
    "         )\n",
    "\n",
    "model.add(MaxPooling2D(pool_size = (8,1)) \n",
    "         )\n",
    "model.add(Conv2D(16, (10,1), \\\n",
    "                 activation='relu')\n",
    "         )\n",
    "\n",
    "model.add(MaxPooling2D(pool_size = (5,1))\n",
    "         )\n",
    "\n",
    "model.add(Dense(512, activation='relu' ))\n",
    "model.add(Dense(128, activation = 'relu'))\n",
    "model.add(Dense(64, activation = 'relu'))\n",
    "model.add(Dense(6, activation='softmax'))\n"
   ]
  },
  {
   "cell_type": "code",
   "execution_count": 24,
   "metadata": {},
   "outputs": [],
   "source": [
    "# training the model \n",
    "model.compile(loss = losses.categorical_crossentropy, \n",
    "              optimizer = optimizers.RMSprop(lr = 0.005), \n",
    "              metrics =['accuracy']) "
   ]
  },
  {
   "cell_type": "code",
   "execution_count": 25,
   "metadata": {},
   "outputs": [
    {
     "name": "stderr",
     "output_type": "stream",
     "text": [
      "ERROR:root:Internal Python error in the inspect module.\n",
      "Below is the traceback from this internal error.\n",
      "\n"
     ]
    },
    {
     "name": "stdout",
     "output_type": "stream",
     "text": [
      "Traceback (most recent call last):\n",
      "  File \"/Users/collopa/anaconda3/lib/python3.7/site-packages/IPython/core/interactiveshell.py\", line 3331, in run_code\n",
      "    exec(code_obj, self.user_global_ns, self.user_ns)\n",
      "  File \"<ipython-input-25-0bb447fbf547>\", line 4, in <module>\n",
      "    validation_data = (test_a_data, test_vec))\n",
      "  File \"/Users/collopa/anaconda3/lib/python3.7/site-packages/keras/engine/training.py\", line 1154, in fit\n",
      "    batch_size=batch_size)\n",
      "  File \"/Users/collopa/anaconda3/lib/python3.7/site-packages/keras/engine/training.py\", line 579, in _standardize_user_data\n",
      "    exception_prefix='input')\n",
      "  File \"/Users/collopa/anaconda3/lib/python3.7/site-packages/keras/engine/training_utils.py\", line 135, in standardize_input_data\n",
      "    'with shape ' + str(data_shape))\n",
      "ValueError: Error when checking input: expected conv2d_1_input to have 4 dimensions, but got array with shape (13460, 128, 3)\n",
      "\n",
      "During handling of the above exception, another exception occurred:\n",
      "\n",
      "Traceback (most recent call last):\n",
      "  File \"/Users/collopa/anaconda3/lib/python3.7/site-packages/IPython/core/interactiveshell.py\", line 2044, in showtraceback\n",
      "    stb = value._render_traceback_()\n",
      "AttributeError: 'ValueError' object has no attribute '_render_traceback_'\n",
      "\n",
      "During handling of the above exception, another exception occurred:\n",
      "\n",
      "Traceback (most recent call last):\n",
      "  File \"/Users/collopa/anaconda3/lib/python3.7/site-packages/IPython/core/ultratb.py\", line 1148, in get_records\n",
      "    return _fixed_getinnerframes(etb, number_of_lines_of_context, tb_offset)\n",
      "  File \"/Users/collopa/anaconda3/lib/python3.7/site-packages/IPython/core/ultratb.py\", line 316, in wrapped\n",
      "    return f(*args, **kwargs)\n",
      "  File \"/Users/collopa/anaconda3/lib/python3.7/site-packages/IPython/core/ultratb.py\", line 350, in _fixed_getinnerframes\n",
      "    records = fix_frame_records_filenames(inspect.getinnerframes(etb, context))\n",
      "  File \"/Users/collopa/anaconda3/lib/python3.7/inspect.py\", line 1502, in getinnerframes\n",
      "    frameinfo = (tb.tb_frame,) + getframeinfo(tb, context)\n",
      "  File \"/Users/collopa/anaconda3/lib/python3.7/inspect.py\", line 1460, in getframeinfo\n",
      "    filename = getsourcefile(frame) or getfile(frame)\n",
      "  File \"/Users/collopa/anaconda3/lib/python3.7/inspect.py\", line 696, in getsourcefile\n",
      "    if getattr(getmodule(object, filename), '__loader__', None) is not None:\n",
      "  File \"/Users/collopa/anaconda3/lib/python3.7/inspect.py\", line 725, in getmodule\n",
      "    file = getabsfile(object, _filename)\n",
      "  File \"/Users/collopa/anaconda3/lib/python3.7/inspect.py\", line 709, in getabsfile\n",
      "    return os.path.normcase(os.path.abspath(_filename))\n",
      "  File \"/Users/collopa/anaconda3/lib/python3.7/posixpath.py\", line 383, in abspath\n",
      "    cwd = os.getcwd()\n",
      "PermissionError: [Errno 1] Operation not permitted\n"
     ]
    },
    {
     "ename": "ValueError",
     "evalue": "Error when checking input: expected conv2d_1_input to have 4 dimensions, but got array with shape (13460, 128, 3)",
     "output_type": "error",
     "traceback": [
      "\u001b[0;31m---------------------------------------------------------------------------\u001b[0m"
     ]
    }
   ],
   "source": [
    "model.fit(train_a_data, train_vec,\n",
    "          epochs = 15,\n",
    "          batch_size = 100,\n",
    "          validation_data = (test_a_data, test_vec))\n",
    "\n",
    "# evaluating and printing results \n",
    "score = model.evaluate(test_a_data, test_vec, verbose = 0) \n",
    "print('Test loss:', score[0]) \n",
    "print('Test accuracy:', score[1]) "
   ]
  },
  {
   "cell_type": "code",
   "execution_count": null,
   "metadata": {},
   "outputs": [],
   "source": [
    "np.shape(val_a_data) == np.shape(val_vec)"
   ]
  },
  {
   "cell_type": "code",
   "execution_count": null,
   "metadata": {},
   "outputs": [],
   "source": [
    "val_vec"
   ]
  },
  {
   "cell_type": "code",
   "execution_count": null,
   "metadata": {},
   "outputs": [],
   "source": [
    "8"
   ]
  }
 ],
 "metadata": {
  "kernelspec": {
   "display_name": "Python 3",
   "language": "python",
   "name": "python3"
  },
  "language_info": {
   "codemirror_mode": {
    "name": "ipython",
    "version": 3
   },
   "file_extension": ".py",
   "mimetype": "text/x-python",
   "name": "python",
   "nbconvert_exporter": "python",
   "pygments_lexer": "ipython3",
   "version": "3.7.7"
  }
 },
 "nbformat": 4,
 "nbformat_minor": 4
}
